<?xml version="1.0"?>

<robot xmlns:xacro="http://www.ros.org/wiki/xacro">

    <xacro:macro name="wheel" params="prefix y_pos">
        
        <link name="${prefix}_wheel_link">
            <visual>
                <origin xyz="0 0 0" rpy="0 0 0"/>

                <geometry>
                    <cylinder radius="${wheel_radius}" length="${wheel_width}" />
                </geometry>
                
                <material name="black">
                    <color rgba="0.1 0.1 0.1 1" />
                </material>
            </visual>

            <collision>
                <origin xyz="0 0 0" rpy="0 0 0"/>

                <geometry>
                    <cylinder radius="${wheel_radius}" length="${wheel_width}" />
                </geometry>
                    
            </collision>

            <xacro:cylinder_inertia mass="${wheel_mass}" radius="${wheel_radius}" length="${wheel_width}"/>
        </link>

        <joint name="${prefix}_wheel_joint" type="continuous">
            <parent  link="chassis_link"/>
            <child link="${prefix}_wheel_link"/>
            <origin xyz="${wheel_x} ${y_pos} 0" rpy="-${pi/2} 0 0"/>
            <axis xyz="0 0 1"/> 
        </joint>


    </xacro:macro>

</robot>